{"uuid": "59f5bc80-bd8f-43d9-a23e-f7fa39446e33", "children": ["8cade1ef-0d3f-44e6-9020-cab86e9d1048"], "befores": [{"name": "login", "status": "broken", "statusDetails": {"message": "selenium.common.exceptions.InvalidArgumentException: Message: invalid argument\n  (Session info: chrome=114.0.5735.199)\nStacktrace:\nBacktrace:\n\tGetHandleVerifier [0x00AAA813+48355]\n\t(No symbol) [0x00A3C4B1]\n\t(No symbol) [0x00945220]\n\t(No symbol) [0x009388E2]\n\t(No symbol) [0x00937138]\n\t(No symbol) [0x00937688]\n\t(No symbol) [0x00946B52]\n\t(No symbol) [0x0099CF01]\n\t(No symbol) [0x0098A73C]\n\t(No symbol) [0x0099C922]\n\t(No symbol) [0x0098A536]\n\t(No symbol) [0x009682DC]\n\t(No symbol) [0x009693DD]\n\tGetHandleVerifier [0x00D0AABD+2539405]\n\tGetHandleVerifier [0x00D4A78F+2800735]\n\tGetHandleVerifier [0x00D4456C+2775612]\n\tGetHandleVerifier [0x00B351E0+616112]\n\t(No symbol) [0x00A45F8C]\n\t(No symbol) [0x00A42328]\n\t(No symbol) [0x00A4240B]\n\t(No symbol) [0x00A34FF7]\n\tBaseThreadInitThunk [0x76AD7D59+25]\n\tRtlInitializeExceptionChain [0x77BAB79B+107]\n\tRtlClearBits [0x77BAB71F+191]\n\n", "trace": "  File \"C:\\Users\\skmee\\AppData\\Local\\Programs\\Python\\Python311\\Lib\\site-packages\\pluggy\\_callers.py\", line 39, in _multicall\n    res = hook_impl.function(*args)\n          ^^^^^^^^^^^^^^^^^^^^^^^^^\n  File \"C:\\Users\\skmee\\AppData\\Local\\Programs\\Python\\Python311\\Lib\\site-packages\\_pytest\\fixtures.py\", line 1128, in pytest_fixture_setup\n    result = call_fixture_func(fixturefunc, request, kwargs)\n             ^^^^^^^^^^^^^^^^^^^^^^^^^^^^^^^^^^^^^^^^^^^^^^^\n  File \"C:\\Users\\skmee\\AppData\\Local\\Programs\\Python\\Python311\\Lib\\site-packages\\_pytest\\fixtures.py\", line 907, in call_fixture_func\n    fixture_result = fixturefunc(**kwargs)\n                     ^^^^^^^^^^^^^^^^^^^^^\n  File \"C:\\Users\\skmee\\PycharmProjects\\udemy_autotests_web\\tests\\conftest.py\", line 22, in login\n    app.user_log_in.open() \\\n    ^^^^^^^^^^^^^^^^^^^^^^\n  File \"C:\\Users\\skmee\\PycharmProjects\\udemy_autotests_web\\udemy_autotests_web\\model\\pages\\user_log_in_page.py\", line 6, in open\n    browser.open('/users/sign_in')\n  File \"C:\\Users\\skmee\\AppData\\Local\\Programs\\Python\\Python311\\Lib\\site-packages\\selene\\core\\entity.py\", line 1154, in open\n    self.config._executor.get_url(relative_or_absolute_url)\n  File \"C:\\Users\\skmee\\AppData\\Local\\Programs\\Python\\Python311\\Lib\\site-packages\\selene\\core\\configuration.py\", line 303, in get_url\n    self.config._driver_get_url_strategy(self.config)(url)\n  File \"C:\\Users\\skmee\\AppData\\Local\\Programs\\Python\\Python311\\Lib\\site-packages\\selene\\core\\configuration.py\", line 255, in get\n    driver.get(url)\n  File \"C:\\Users\\skmee\\AppData\\Local\\Programs\\Python\\Python311\\Lib\\site-packages\\selenium\\webdriver\\remote\\webdriver.py\", line 449, in get\n    self.execute(Command.GET, {\"url\": url})\n  File \"C:\\Users\\skmee\\AppData\\Local\\Programs\\Python\\Python311\\Lib\\site-packages\\selenium\\webdriver\\remote\\webdriver.py\", line 440, in execute\n    self.error_handler.check_response(response)\n  File \"C:\\Users\\skmee\\AppData\\Local\\Programs\\Python\\Python311\\Lib\\site-packages\\selenium\\webdriver\\remote\\errorhandler.py\", line 245, in check_response\n    raise exception_class(message, screen, stacktrace)\n"}, "start": 1689501965049, "stop": 1689501971977}], "start": 1689501965049, "stop": 1689501972571}