{"uuid": "d6aad44c-e8ac-43a1-819e-8c03e3fd6874", "children": ["5da1743f-8b44-4691-8ed1-3911bec316c2"], "befores": [{"name": "login", "status": "broken", "statusDetails": {"message": "selenium.common.exceptions.InvalidArgumentException: Message: invalid argument\n  (Session info: chrome=114.0.5735.199)\nStacktrace:\nBacktrace:\n\tGetHandleVerifier [0x0051A813+48355]\n\t(No symbol) [0x004AC4B1]\n\t(No symbol) [0x003B5220]\n\t(No symbol) [0x003A88E2]\n\t(No symbol) [0x003A7138]\n\t(No symbol) [0x003A7688]\n\t(No symbol) [0x003B6B52]\n\t(No symbol) [0x0040CF01]\n\t(No symbol) [0x003FA73C]\n\t(No symbol) [0x0040C922]\n\t(No symbol) [0x003FA536]\n\t(No symbol) [0x003D82DC]\n\t(No symbol) [0x003D93DD]\n\tGetHandleVerifier [0x0077AABD+2539405]\n\tGetHandleVerifier [0x007BA78F+2800735]\n\tGetHandleVerifier [0x007B456C+2775612]\n\tGetHandleVerifier [0x005A51E0+616112]\n\t(No symbol) [0x004B5F8C]\n\t(No symbol) [0x004B2328]\n\t(No symbol) [0x004B240B]\n\t(No symbol) [0x004A4FF7]\n\tBaseThreadInitThunk [0x76AD7D59+25]\n\tRtlInitializeExceptionChain [0x77BAB79B+107]\n\tRtlClearBits [0x77BAB71F+191]\n\n", "trace": "  File \"C:\\Users\\skmee\\AppData\\Local\\Programs\\Python\\Python311\\Lib\\site-packages\\pluggy\\_callers.py\", line 39, in _multicall\n    res = hook_impl.function(*args)\n          ^^^^^^^^^^^^^^^^^^^^^^^^^\n  File \"C:\\Users\\skmee\\AppData\\Local\\Programs\\Python\\Python311\\Lib\\site-packages\\_pytest\\fixtures.py\", line 1128, in pytest_fixture_setup\n    result = call_fixture_func(fixturefunc, request, kwargs)\n             ^^^^^^^^^^^^^^^^^^^^^^^^^^^^^^^^^^^^^^^^^^^^^^^\n  File \"C:\\Users\\skmee\\AppData\\Local\\Programs\\Python\\Python311\\Lib\\site-packages\\_pytest\\fixtures.py\", line 907, in call_fixture_func\n    fixture_result = fixturefunc(**kwargs)\n                     ^^^^^^^^^^^^^^^^^^^^^\n  File \"C:\\Users\\skmee\\PycharmProjects\\udemy_autotests_web\\tests\\conftest.py\", line 22, in login\n    app.user_log_in.open() \\\n    ^^^^^^^^^^^^^^^^^^^^^^\n  File \"C:\\Users\\skmee\\PycharmProjects\\udemy_autotests_web\\udemy_autotests_web\\model\\pages\\user_log_in_page.py\", line 6, in open\n    browser.open('/users/sign_in')\n  File \"C:\\Users\\skmee\\AppData\\Local\\Programs\\Python\\Python311\\Lib\\site-packages\\selene\\core\\entity.py\", line 1154, in open\n    self.config._executor.get_url(relative_or_absolute_url)\n  File \"C:\\Users\\skmee\\AppData\\Local\\Programs\\Python\\Python311\\Lib\\site-packages\\selene\\core\\configuration.py\", line 303, in get_url\n    self.config._driver_get_url_strategy(self.config)(url)\n  File \"C:\\Users\\skmee\\AppData\\Local\\Programs\\Python\\Python311\\Lib\\site-packages\\selene\\core\\configuration.py\", line 255, in get\n    driver.get(url)\n  File \"C:\\Users\\skmee\\AppData\\Local\\Programs\\Python\\Python311\\Lib\\site-packages\\selenium\\webdriver\\remote\\webdriver.py\", line 449, in get\n    self.execute(Command.GET, {\"url\": url})\n  File \"C:\\Users\\skmee\\AppData\\Local\\Programs\\Python\\Python311\\Lib\\site-packages\\selenium\\webdriver\\remote\\webdriver.py\", line 440, in execute\n    self.error_handler.check_response(response)\n  File \"C:\\Users\\skmee\\AppData\\Local\\Programs\\Python\\Python311\\Lib\\site-packages\\selenium\\webdriver\\remote\\errorhandler.py\", line 245, in check_response\n    raise exception_class(message, screen, stacktrace)\n"}, "start": 1689446580108, "stop": 1689446588832}], "start": 1689446580108, "stop": 1689446589841}