{"uuid": "94c12106-c2a0-4690-a2bb-959bf16cfc21", "children": ["54909ec0-6dae-48b4-b021-6bdc5862c354"], "befores": [{"name": "login", "status": "broken", "statusDetails": {"message": "selenium.common.exceptions.InvalidArgumentException: Message: invalid argument\n  (Session info: chrome=114.0.5735.199)\nStacktrace:\nBacktrace:\n\tGetHandleVerifier [0x009DA813+48355]\n\t(No symbol) [0x0096C4B1]\n\t(No symbol) [0x00875220]\n\t(No symbol) [0x008688E2]\n\t(No symbol) [0x00867138]\n\t(No symbol) [0x00867688]\n\t(No symbol) [0x00876B52]\n\t(No symbol) [0x008CCF01]\n\t(No symbol) [0x008BA73C]\n\t(No symbol) [0x008CC922]\n\t(No symbol) [0x008BA536]\n\t(No symbol) [0x008982DC]\n\t(No symbol) [0x008993DD]\n\tGetHandleVerifier [0x00C3AABD+2539405]\n\tGetHandleVerifier [0x00C7A78F+2800735]\n\tGetHandleVerifier [0x00C7456C+2775612]\n\tGetHandleVerifier [0x00A651E0+616112]\n\t(No symbol) [0x00975F8C]\n\t(No symbol) [0x00972328]\n\t(No symbol) [0x0097240B]\n\t(No symbol) [0x00964FF7]\n\tBaseThreadInitThunk [0x76AD7D59+25]\n\tRtlInitializeExceptionChain [0x77BAB79B+107]\n\tRtlClearBits [0x77BAB71F+191]\n\n", "trace": "  File \"C:\\Users\\skmee\\AppData\\Local\\Programs\\Python\\Python311\\Lib\\site-packages\\pluggy\\_callers.py\", line 39, in _multicall\n    res = hook_impl.function(*args)\n          ^^^^^^^^^^^^^^^^^^^^^^^^^\n  File \"C:\\Users\\skmee\\AppData\\Local\\Programs\\Python\\Python311\\Lib\\site-packages\\_pytest\\fixtures.py\", line 1128, in pytest_fixture_setup\n    result = call_fixture_func(fixturefunc, request, kwargs)\n             ^^^^^^^^^^^^^^^^^^^^^^^^^^^^^^^^^^^^^^^^^^^^^^^\n  File \"C:\\Users\\skmee\\AppData\\Local\\Programs\\Python\\Python311\\Lib\\site-packages\\_pytest\\fixtures.py\", line 907, in call_fixture_func\n    fixture_result = fixturefunc(**kwargs)\n                     ^^^^^^^^^^^^^^^^^^^^^\n  File \"C:\\Users\\skmee\\PycharmProjects\\udemy_autotests_web\\tests\\conftest.py\", line 22, in login\n    app.user_log_in.open() \\\n    ^^^^^^^^^^^^^^^^^^^^^^\n  File \"C:\\Users\\skmee\\PycharmProjects\\udemy_autotests_web\\udemy_autotests_web\\model\\pages\\user_log_in_page.py\", line 6, in open\n    browser.open('/users/sign_in')\n  File \"C:\\Users\\skmee\\AppData\\Local\\Programs\\Python\\Python311\\Lib\\site-packages\\selene\\core\\entity.py\", line 1154, in open\n    self.config._executor.get_url(relative_or_absolute_url)\n  File \"C:\\Users\\skmee\\AppData\\Local\\Programs\\Python\\Python311\\Lib\\site-packages\\selene\\core\\configuration.py\", line 303, in get_url\n    self.config._driver_get_url_strategy(self.config)(url)\n  File \"C:\\Users\\skmee\\AppData\\Local\\Programs\\Python\\Python311\\Lib\\site-packages\\selene\\core\\configuration.py\", line 255, in get\n    driver.get(url)\n  File \"C:\\Users\\skmee\\AppData\\Local\\Programs\\Python\\Python311\\Lib\\site-packages\\selenium\\webdriver\\remote\\webdriver.py\", line 449, in get\n    self.execute(Command.GET, {\"url\": url})\n  File \"C:\\Users\\skmee\\AppData\\Local\\Programs\\Python\\Python311\\Lib\\site-packages\\selenium\\webdriver\\remote\\webdriver.py\", line 440, in execute\n    self.error_handler.check_response(response)\n  File \"C:\\Users\\skmee\\AppData\\Local\\Programs\\Python\\Python311\\Lib\\site-packages\\selenium\\webdriver\\remote\\errorhandler.py\", line 245, in check_response\n    raise exception_class(message, screen, stacktrace)\n"}, "start": 1689501376050, "stop": 1689501382303}], "start": 1689501376050, "stop": 1689501382995}